Pig Stack Trace
---------------
ERROR 6000: 
<file /Users/oozie/OOZIE-2129/sharelib/pig/target/test-data/oozietests/org.apache.oozie.action.hadoop.TestPigMain/testPig_withNullExternalID/script.pig, line 2, column 0> Output Location Validation Failed for: '/user/test/a76c528a-fbe5-4da7-97fa-d20c9407b7de/input More info to follow:
Output directory hdfs://localhost:64455/user/test/a76c528a-fbe5-4da7-97fa-d20c9407b7de/input already exists

org.apache.pig.impl.plan.VisitorException: ERROR 6000: 
<file /Users/oozie/OOZIE-2129/sharelib/pig/target/test-data/oozietests/org.apache.oozie.action.hadoop.TestPigMain/testPig_withNullExternalID/script.pig, line 2, column 0> Output Location Validation Failed for: '/user/test/a76c528a-fbe5-4da7-97fa-d20c9407b7de/input More info to follow:
Output directory hdfs://localhost:64455/user/test/a76c528a-fbe5-4da7-97fa-d20c9407b7de/input already exists
	at org.apache.pig.newplan.logical.rules.InputOutputFileValidator$InputOutputFileVisitor.visit(InputOutputFileValidator.java:95)
	at org.apache.pig.newplan.logical.relational.LOStore.accept(LOStore.java:66)
	at org.apache.pig.newplan.DepthFirstWalker.depthFirst(DepthFirstWalker.java:64)
	at org.apache.pig.newplan.DepthFirstWalker.depthFirst(DepthFirstWalker.java:66)
	at org.apache.pig.newplan.DepthFirstWalker.walk(DepthFirstWalker.java:53)
	at org.apache.pig.newplan.PlanVisitor.visit(PlanVisitor.java:52)
	at org.apache.pig.newplan.logical.rules.InputOutputFileValidator.validate(InputOutputFileValidator.java:45)
	at org.apache.pig.backend.hadoop.executionengine.HExecutionEngine.compile(HExecutionEngine.java:303)
	at org.apache.pig.PigServer.compilePp(PigServer.java:1382)
	at org.apache.pig.PigServer.executeCompiledLogicalPlan(PigServer.java:1307)
	at org.apache.pig.PigServer.execute(PigServer.java:1299)
	at org.apache.pig.PigServer.executeBatch(PigServer.java:377)
	at org.apache.pig.PigServer.executeBatch(PigServer.java:355)
	at org.apache.pig.tools.grunt.GruntParser.executeBatch(GruntParser.java:140)
	at org.apache.pig.tools.grunt.GruntParser.parseStopOnError(GruntParser.java:202)
	at org.apache.pig.tools.grunt.GruntParser.parseStopOnError(GruntParser.java:173)
	at org.apache.pig.tools.grunt.Grunt.exec(Grunt.java:84)
	at org.apache.pig.Main.run(Main.java:478)
	at org.apache.pig.PigRunner.run(PigRunner.java:49)
	at org.apache.oozie.action.hadoop.PigMain.runPigJob(PigMain.java:289)
	at org.apache.oozie.action.hadoop.PigMain.run(PigMain.java:229)
	at org.apache.oozie.action.hadoop.LauncherMain.run(LauncherMain.java:45)
	at org.apache.oozie.action.hadoop.PigMain.main(PigMain.java:76)
	at org.apache.oozie.action.hadoop.TestPigMain.call(TestPigMain.java:119)
	at org.apache.oozie.action.hadoop.TestPigMain.call(TestPigMain.java:38)
	at org.apache.oozie.action.hadoop.MainTestCase$1.run(MainTestCase.java:33)
	at org.apache.oozie.action.hadoop.MainTestCase$1.run(MainTestCase.java:31)
	at java.security.AccessController.doPrivileged(Native Method)
	at javax.security.auth.Subject.doAs(Subject.java:394)
	at org.apache.hadoop.security.UserGroupInformation.doAs(UserGroupInformation.java:1548)
	at org.apache.oozie.action.hadoop.MainTestCase.execute(MainTestCase.java:31)
	at org.apache.oozie.action.hadoop.PigTestCase.testPig_withNullExternalID(PigTestCase.java:106)
	at sun.reflect.NativeMethodAccessorImpl.invoke0(Native Method)
	at sun.reflect.NativeMethodAccessorImpl.invoke(NativeMethodAccessorImpl.java:39)
	at sun.reflect.DelegatingMethodAccessorImpl.invoke(DelegatingMethodAccessorImpl.java:25)
	at java.lang.reflect.Method.invoke(Method.java:597)
	at junit.framework.TestCase.runTest(TestCase.java:168)
	at junit.framework.TestCase.runBare(TestCase.java:134)
	at junit.framework.TestResult$1.protect(TestResult.java:110)
	at junit.framework.TestResult.runProtected(TestResult.java:128)
	at junit.framework.TestResult.run(TestResult.java:113)
	at junit.framework.TestCase.run(TestCase.java:124)
	at junit.framework.TestSuite.runTest(TestSuite.java:243)
	at junit.framework.TestSuite.run(TestSuite.java:238)
	at org.junit.internal.runners.JUnit38ClassRunner.run(JUnit38ClassRunner.java:83)
	at org.junit.runners.Suite.runChild(Suite.java:128)
	at org.junit.runners.Suite.runChild(Suite.java:24)
	at org.junit.runners.ParentRunner$3.run(ParentRunner.java:231)
	at java.util.concurrent.Executors$RunnableAdapter.call(Executors.java:439)
	at java.util.concurrent.FutureTask$Sync.innerRun(FutureTask.java:303)
	at java.util.concurrent.FutureTask.run(FutureTask.java:138)
	at java.util.concurrent.ThreadPoolExecutor$Worker.runTask(ThreadPoolExecutor.java:895)
	at java.util.concurrent.ThreadPoolExecutor$Worker.run(ThreadPoolExecutor.java:918)
	at java.lang.Thread.run(Thread.java:695)
Caused by: org.apache.hadoop.mapred.FileAlreadyExistsException: Output directory hdfs://localhost:64455/user/test/a76c528a-fbe5-4da7-97fa-d20c9407b7de/input already exists
	at org.apache.hadoop.mapreduce.lib.output.FileOutputFormat.checkOutputSpecs(FileOutputFormat.java:146)
	at org.apache.pig.newplan.logical.rules.InputOutputFileValidator$InputOutputFileVisitor.visit(InputOutputFileValidator.java:80)
	... 53 more
================================================================================
